Workbook
Name AbrazaderaEstado: [1]C_EstadoConservacion!$C$2:$C$5
Name AbrazaderaEstado: [1]C_EstadoConservacion!$C$2:$C$5
Name AbrazaderaEstado: [1]C_EstadoConservacion!$C$2:$C$5
Name AbrazaderaEstado: [1]C_EstadoConservacion!$C$2:$C$5
Name AbrazaderaEstado: [1]C_EstadoConservacion!$C$2:$C$5
Name AbrazaderaEstado: [1]C_EstadoConservacion!$C$2:$C$5
Name AbrazaderaEstado: [1]C_EstadoConservacion!$C$2:$C$5
Name AbrazaderaEstado: [1]C_EstadoConservacion!$C$2:$C$5
Name AbrazaderaEstado: [1]C_EstadoConservacion!$C$2:$C$5
Name AbrazaderaEstado: [1]C_EstadoConservacion!$C$2:$C$5
Name AbrazaderaEstado: [1]C_EstadoConservacion!$C$2:$C$5
Name AbrazaderaEstado: [1]C_EstadoConservacion!$C$2:$C$5
Name AbrazaderaEstado: [1]C_EstadoConservacion!$C$2:$C$5
Name AbrazaderaEstado: [1]C_EstadoConservacion!$C$2:$C$5
Name AbrazaderaEstado: [1]C_EstadoConservacion!$C$2:$C$5
Name AbrazaderaEstado: [1]C_EstadoConservacion!$C$2:$C$5
Name AbrazaderaEstado: [1]C_EstadoConservacion!$C$2:$C$5
Name AbrazaderaEstado: [1]C_EstadoConservacion!$C$2:$C$5
Name AbrazaderaEstado: [1]C_EstadoConservacion!$C$2:$C$5
Name AbrazaderaEstado: [1]C_EstadoConservacion!$C$2:$C$5
Name AbrazaderaEstado: [1]C_EstadoConservacion!$C$2:$C$5
Name AbrazaderaEstado: [1]C_EstadoConservacion!$C$2:$C$5
Name AbrazaderaEstado: [1]C_EstadoConservacion!$C$2:$C$5
Name AbrazaderaEstado: [1]C_EstadoConservacion!$C$2:$C$5
Name AbrazaderaEstado: #REF!
Name AcetatoEstado: [1]C_EstadoConservacion!$B$2:$B$4
Name AcetatoEstado: [1]C_EstadoConservacion!$B$2:$B$4
Name AcetatoEstado: [1]C_EstadoConservacion!$B$2:$B$4
Name AcetatoEstado: [1]C_EstadoConservacion!$B$2:$B$4
Name AcetatoEstado: [1]C_EstadoConservacion!$B$2:$B$4
Name AcetatoEstado: [1]C_EstadoConservacion!$B$2:$B$4
Name AcetatoEstado: [1]C_EstadoConservacion!$B$2:$B$4
Name AcetatoEstado: [1]C_EstadoConservacion!$B$2:$B$4
Name AcetatoEstado: [1]C_EstadoConservacion!$B$2:$B$4
Name AcetatoEstado: [1]C_EstadoConservacion!$B$2:$B$4
Name AcetatoEstado: [1]C_EstadoConservacion!$B$2:$B$4
Name AcetatoEstado: [1]C_EstadoConservacion!$B$2:$B$4
Name AcetatoEstado: [1]C_EstadoConservacion!$B$2:$B$4
Name AcetatoEstado: [1]C_EstadoConservacion!$B$2:$B$4
Name AcetatoEstado: [1]C_EstadoConservacion!$B$2:$B$4
Name AcetatoEstado: [1]C_EstadoConservacion!$B$2:$B$4
Name AcetatoEstado: [1]C_EstadoConservacion!$B$2:$B$4
Name AcetatoEstado: [1]C_EstadoConservacion!$B$2:$B$4
Name AcetatoEstado: [1]C_EstadoConservacion!$B$2:$B$4
Name AcetatoEstado: [1]C_EstadoConservacion!$B$2:$B$4
Name AcetatoEstado: [1]C_EstadoConservacion!$B$2:$B$4
Name AcetatoEstado: [1]C_EstadoConservacion!$B$2:$B$4
Name AcetatoEstado: [1]C_EstadoConservacion!$B$2:$B$4
Name AcetatoEstado: [1]C_EstadoConservacion!$B$2:$B$4
Name AcetatoEstado: #REF!
Name CantidadCualitativa: [1]C_DisposicionMaterial!$K$2:$K$6
Name CantidadCualitativa: [1]C_DisposicionMaterial!$K$2:$K$6
Name CantidadCualitativa: [1]C_DisposicionMaterial!$K$2:$K$6
Name CantidadCualitativa: [1]C_DisposicionMaterial!$K$2:$K$6
Name CantidadCualitativa: [1]C_DisposicionMaterial!$K$2:$K$6
Name CantidadCualitativa: [1]C_DisposicionMaterial!$K$2:$K$6
Name CantidadCualitativa: [1]C_DisposicionMaterial!$K$2:$K$6
Name CantidadCualitativa: [1]C_DisposicionMaterial!$K$2:$K$6
Name CantidadCualitativa: [1]C_DisposicionMaterial!$K$2:$K$6
Name CantidadCualitativa: [1]C_DisposicionMaterial!$K$2:$K$6

Sheet CAT_COLECCION
A1: ColeccionID | B1: CodigoColeccion | C1: NombreColeccion | D1: Institucion | E1: ResponsableColeccion | F1: Descripcion | G1: EstadoColeccion
A2: 1 | B2: COL-HDC | C2: Colección Personal Hermann Duque Caro | D2: SGC | E2: Grupo de Bioestratigrafía - Dirección de Geociencias Básicas | F2: Placas donadas por la Sra. Bertha Nope Viuda de Duque al SGC, DGB en noviembre de 2018 | G2: Cerrada
A3: 2 | B3: COL-MUSEO | C3: Colección Museo Geológico José Royo y Gómez | D3: SGC | E3: Grupo de Bioestratigrafía - Dirección de Geociencias Básicas | F3: Placas que se encontraban en el Museo Geológico Nacional José Royo y Gómez. Colección histórica del Servicio Geológico Nacional (=Ingeominas, =SGC). La colección pasó a la custodia del Grupo de Bioestratigrafía-DGB en marzo de 2022 | G3: Cerrada
A4: 3 | B4: COL-LITOTECA | C4: Colección Litoteca Nacional Guatiguará | D4: SGC | E4: Grupo de Bioestratigrafía - Dirección de Geociencias Básicas | F4: Placas que se encontraban en la Litoteca Nacional-Guatiguará (SGC, sede Santander). El material corresponde principalmente a muestras de la industria petrolera. Pasó a la custodia del Grupo de Bioestratigrafía-DGB en diciembre de 2025 | G4: Activa
A5: 4 | B5: COL-GRUPO_BIO | C5: Colección Grupo Bioestratigrafía DGB | D5: SGC | E5: Grupo de Bioestratigrafía - Dirección de Geociencias Básicas | F5: Placas que se generan a partir de los proyectos de investigación a partir del año 2024 | G5: Activa

Sheet PERSONA
A1: PersonaID | B1: CodigoPersona | C1: Nombre | D1: Apellidos | E1: Correo | F1: Activo | G1: Observaciones
A2: 1 | B2: DML | C2: Danixa Maribel | D2: López Cuevas
A3: 2 | B3: GGO | C3: Georgina | D3: Guzmán Ospitia
A4: 3 | B4: ASD | C4: Marlon Alejandro | D4: Suárez Díaz
A5: 4 | B5: ADV | C5: Brayan Alejandro | D5: Díaz Vásquez
A6: 5 | B6: JSD | C6: Jefferson Steven | D6: Díaz Villamizar
A7: 6 | B7: ALM | C7: Adrián | D7: Linares Murcia
A8: 7 | B8: DEV | C8: Diana | D8: Espitia Vanegas
A9: 8 | B9: JDF | C9: Jairo Alexander | D9: Duarte Forero

Sheet CAT_ROL
A1: RolID | B1: Nombre | C1: Funcion | D1: NivelResponsabilidad | E1: Actividades
A2: 1 | B2: Catalogador científico | C2: Registro sistemático, descripción detallada y transcripción estructurada de información histórica, física y científica asociada a las colecciones micropaleontológicas | D2: Operativo | E2: Descripción detallada de placas micropaleontológicas; Observación y registro sistemático de características físicas del material; Transcripción estructurada de anotaciones manuscritas; Registro de disposición y distribución del material en cavidades; Registro de estado de preservación y conservación observable; Registro de ubicación física dentro de colecciones; Registro de información asociada a muestras y procedencia; Identificación y registro de elementos taxonómicos reportados; Ingreso controlado de datos en tablas HIST_; Aplicación de protocolos de catalogación; Verificación básica de consistencia en el ingreso de datos
A3: 2 | B3: Revisor científico | C3: Validación científica y control de calidad del diligenciamiento. Micropaleontólogo responsable de evaluar, corregir, homologar o actualizar la información según conocimiento experto. | D3: Científico | E3: Revisión taxonómica; Validación bioestratigráfica; Revisión de información geográfica; Revisión de consistencia estratigráfica; Normalización nomenclatural; Alimentación de tablas DIC_; Control de calidad científico; Validación de transcripciones históricas; Revisión de relaciones taxonómicas y estratigráficas
A4: 3 | B4: Diseñador de arquitectura de datos científicos | C4: Diseño conceptual, estructural y funcional de la arquitectura de datos científicos y de conservación del sistema, incluyendo su implementación preliminar y validación operativa en Microsoft Access. | D4: ArquitecturaDatos | E4: Diseño de arquitectura relacional; Definición de módulos; Definición de tablas y campos; Definición de relaciones entre tablas; Diseño de estructuras taxonómicas y estratigráficas; Definición de estándares de nomenclatura; Diseño de protocolos de catalogación; Definición de secuencias de ingreso y validación de datos; Definición estructural de datos científicos; Atomización y estructuración de información científica; Transformación de texto libre en datos consultables; Diseño de listas desplegables y controles de validación; Estandarización de ingreso de datos; Prevención de errores de digitalización; Definición de criterios de trazabilidad; Definición de nomenclaturas documentales y estructuras de almacenamiento digital; Implementación preliminar de arquitectura relacional en Microsoft Access; Diseño funcional de formularios y controles de ingreso de datos; Implementación de listas desplegables y validaciones preliminares; Pruebas funcionales de experiencia de usuario científico (UX científico); Validación conceptual de relaciones entre tablas; Actualización de arquitectura del sistema
A5: 4 | B5: Desarrollador Plataforma GeoTrace | C5: Implementación técnica, automatización y desarrollo funcional de la plataforma y herramientas asociadas | D5: Técnico | E5: Implementación de tablas y relaciones; Desarrollo en GeoTrace; Desarrollo de formularios; Desarrollo de consultas; Desarrollo de consultas complejas; Configuración de integridad referencial; Automatización de procesos; Implementación de controles de validación; Importación masiva de datos; Verificación de integridad de datos importados; Validación de correspondencia entre datos y campos; Desarrollo de campos calculados; Generación de métricas automáticas; Integración funcional entre módulos de la plataforma; Integración y configuración del geovisor; Integración de tablas espaciales; Desarrollo de visualizaciones geográficas; Generación de estadísticas automáticas; Optimización de rendimiento; Implementación de seguridad técnica; Mantenimiento técnico del sistema
A6: 5 | B6: Administrador del sistema | C6: Administración técnica, seguridad y control operativo del sistema | D6: Administrativo | E6: Administración de usuarios; Control de permisos; Gestión de respaldos; Control de versiones; Supervisión de seguridad; Mantenimiento de integridad operativa; Monitoreo del sistema; Gestión de recuperación de datos; Administración de accesos; Supervisión de almacenamiento y respaldo
A7: 6 | B7: Revisor espacial | C7: Validación y gestión de información geográfica y espacial | D7: Geoespacial | E7: Georreferenciación de localidades; Validación de coordenadas; Conversión de sistemas de coordenadas; Verificación de datum y proyecciones; Digitalización de mapas; Integración cartográfica; Control de precisión espacial; Apoyo cartográfico para geovisor
A8: 7 | B8: Gestor Archivo Visual | C8: Digitalización, organización y gestión técnica de archivos visuales históricos asociados a las colecciones micropaleontológicas. | D8: Visual | E8: Digitalización de diapositivas y fotografías históricas; Organización jerárquica de archivos visuales; Aplicación de nomenclatura normalizada para archivos digitales; Registro de información técnica de imágenes digitalizadas; Control de resolución y formatos de imagen; Registro de edición y procesamiento digital; Organización de carpetas visuales; Verificación básica de calidad de imágenes digitalizadas; Gestión de almacenamiento de archivos visuales; Vinculación inicial de archivos visuales con registros de la base de datos
A9: 8 | B9: Gestor Documental | C9: Digitalización, organización, conservación básica y gestión estructurada de documentación técnica, científica e histórica asociada a las colecciones | D9: Documental | E9: Digitalización de documentos técnicos e históricos; Organización jerárquica de archivos documentales; Aplicación de nomenclatura normalizada para archivos digitales; Organización de carpetas digitales por pozo y proyecto; Verificación básica de calidad de documentos digitalizados; Gestión de almacenamiento documental; Organización de mapas, informes y documentación administrativa digitalizada; Evaluación básica del estado físico de documentos; Conservación preventiva de documentación histórica; Restauración básica de documentos deteriorados; Estabilización de pliegues y rasgaduras antes de digitalización; Manejo cuidadoso de documentación frágil
A10: 9 | B10: Revisor Técnico Documental | C10: Revisión e interpretación de información geológica, geográfica y estratigráfica contenida en documentos para su integración y vinculación con las colecciones y registros de la base de datos. | D10: Científico | E10: Revisión de contenido geológico y estratigráfico de documentos; Identificación de información geográfica relevante; Vinculación documental con placas y muestras; Correlación entre documentos y registros históricos; Validación de referencias geológicas y espaciales; Identificación de pozos, localidades y unidades estratigráficas; Integración de información documental en la base de datos; Verificación de consistencia entre documentos y registros catalogados; Apoyo en reconstrucción histórica de información científica
A11: 10 | B11: Curador de colección micropaleontológica | C11: Conservación, preservación e intervención física del material micropaleontológico | D11: Conservación | E11: Evaluación de conservación física; Reemplazo de placas deterioradas; Cambio de portaobjetos; Limpieza y estabilización de material; Manejo de material frágil; Conservación preventiva; Intervención conservación; Transferencia de material micropaleontológico; Control de condiciones físicas de almacenamiento; Supervisión de manipulación de colecciones

Sheet REL_PERSONA_ROL
A1: PersonaRolID | B1: PersonaID | C1: CodigoPersona | D1: RolID | E1: FechaInicio | F1: FechaFin | G1: Activo | H1: Observaciones
A2: 1 | B2: 1 | C2: DML | D2: 1
A3: 2 | B3: 2 | C3: GGO | D3: 1
A4: 3 | B4: 2 | C4: GGO | D4: 9
A5: 4 | B5: 3 | C5: ASD | D5: 1
A6: 5 | B6: 3 | C6: ASD | D6: 7
A7: 6 | B7: 4 | C7: ADV | D7: 1
A8: 7 | B8: 5 | C8: JSD | D8: 1
A9: 8 | B9: 5 | C9: JSD | D9: 6
A10: 9 | B10: 6 | C10: ALM | D10: 4
A11: 10 | B11: 6 | C11: ALM | D11: 5
A12: 11 | B12: 6 | C12: ALM | D12: 6
A13: 12 | B13: 7 | C13: DEV | D13: 2
... A19: 18 | B19: 8 | C19: JDF | D19: 10

Sheet CAT_PERMISO
A1: PermisoID | B1: Nombre | C1: Descripcion | D1: Modulo | E1: NivelCriticidad
A2: 1 | B2: Crear placa | C2: Permite registrar nuevas placas en el sistema | E2: Catalogador
A3: 2 | B3: Editar placa | C3: Permite modificar información de placas existentes | E3: Catalogador
A4: 3 | B4: Crear muestra | C4: Permite registrar nuevas muestras | E4: Catalogador
A5: 4 | B5: Editar muestra | C5: Permite + accion de edición | E5: Catalogador
A6: 5 | B6: Transcribir anotaciones | E6: Catalogador
A7: 6 | B7: Revisar registros | E7: Revisor cientifico
A8: 7 | B8: Aprobar catalogación | C8: Permite validar y cerrar registros catalogados | E8: Revisor cientifico
A9: 8 | B9: Editar taxonomía | C9: Permite modificar información taxonómica | E9: Revisor cientifico
A10: 9 | B10: Editar estratigrafía | E10: Revisor cientifico
A11: 10 | B11: Editar bioestratigrafía | E11: Revisor cientifico
A12: 11 | B12: Aprobar revisión científica | E12: Revisor cientifico
A13: 12 | B13: Eliiminar placa | E13: Revisor cientifico
A14: 13 | B14: Modificar catálogos | E14: Diseñador arquitectura datos científicos
A15: 14 | B15: Modificar diccionarios | E15: Diseñador arquitectura datos científicos
A16: 15 | B16: la ho | E16: Diseñador arquitectura datos científicos
A17: 16 | B17: Definir validaciones | E17: Diseñador arquitectura datos científicos
A18: 17 | B18: Control estructural sistema | E18: Diseñador arquitectura datos científicos
A19: 18 | B19: Ejecutar carga masiva | E19: Desarrollador plataforma GeoTrace
A20: 19 | B20: Administrar usuarios | E20: Desarrollador plataforma GeoTrace
A21: 20 | B21: Configurar formularios | E21: Desarrollador plataforma GeoTrace; Diseñador arquitectura datos científicos
... A38: 37 | B38: Aprobar información espacial | E38: Revisor espacial

Sheet REL_ROL_PERMISO
A1: RolPermisoID | B1: RolID | C1: PermisoID | D1: Activo
A2: 1
A3: 2
A4: 3
A5: 4
A6: 5
A7: 6
A8: 7
A9: 8
A10: 9
A11: 10
A12: 11
A13: 12
... A16: 15

Sheet CAT_ESTADO_CATALOGACION
A1: EstadoCatalogacionID | B1: Estado | C1: Significado | D1: Quien
A2: 1 | B2: En proceso | C2: Captura activa | D2: Catalogador
A3: 2 | B3: Incompleto | C3: Faltan datos | D3: Sistema/Catalogador
A4: 3 | B4: En revisión | C4: control de calidad | D4: Revisor
A5: 4 | B5: Validado | C5: Revisión aprobada | D5: Revisor
A6: 5 | B6: Congelado | C6: Registro congelado | D6: Administrador

Sheet CAT_MUEBLE
A1: MuebleID | B1: CodigoMueble | C1: MaterialMuebleID | D1: ColorMuebleID | E1: TieneSecciones | F1: TieneZonas | G1: CapacidadBandejas | H1: CapacidadPosiciones | I1: Observaciones
A2: 1 | B2: HDC-1
A3: 2 | B3: HDC-2
A4: 3 | B4: HDC-3
A5: 4 | B5: HDC-4
A6: 5 | B6: A
A7: 6 | B7: B
A8: 7 | B8: C
A9: 8 | B9: MA
A10: 9 | B10: MB
A11: 10 | B11: MC
A12: 11 | B12: MD
A13: 12 | B13: CG-M-1
... A23: 22 | B23: LNG-5

Sheet CAT_MATERIAL_MUEBLE
A1: MaterialMuebleID | B1: Nombre | C1: Descripcion
A2: 1 | B2: Madera
A3: 2 | B3: Metálico

Sheet CAT_COLOR_MUEBLE
A1: ColorMuebleID | B1: Nombre
A2: 1 | B2: Natural
A3: 2 | B3: Negro
A4: 3 | B4: Caoba claro
A5: 4 | B5: Caoba oscuro

Sheet PLACA
A1: CodigoUbicacion | B1: CodigoColeccion | C1: PlacaID | D1: CodigoPlaca | E1: ClasePlacaID | F1: EtapaUsoPlacaID | G1: DisenoPlacaID | H1: ConfiguracionCavidadesID | I1: MaterialPlacaID | J1: ColorPlacaID | K1: ConfiguracionRejillaID | L1: TipoProteccionID | M1: SistemaEnsambleID | N1: CatalogadorID | O1: FechaIngreso | P1: EstadoCatalogacionID | Q1: RevisorID | R1: FechaRevision
A2: M1-Sup-Izq-B11-Izq-19 | B2: COL-003 | D2: =IF(H2="","","PL-"&TEXT(#REF!,"000000")) -> #REF! | E2: Asociación | F2: Vacia y preparada para organización | G2: Circular | H2: 4 | I2: Cartón | J2: Negra | L2: Acetato | N2: CAT-01
B3: COL-003 | D3: =IF(H3="","","PL-"&TEXT(#REF!,"000000")) -> #REF! | E3: Asociación | F3: En uso - material seleccionado | G3: Mixta | H3: 2 | I3: Cartón | J3: Blanca | K3: 15 | L3: Vidrio | M3: Aluminio | N3: CAT-01
B4: COL-003 | D4: =IF(H4="","","PL-"&TEXT(#REF!,"000000")) -> #REF! | E4: Tipo | F4: En uso - material organizado | G4: Rectangular | H4: 1 | I4: Plástico | J4: Blanca | K4: 50 | L4: Vidrio | M4: Aluminio
B5: COL-003 | D5: =IF(H5="","","PL-"&TEXT(#REF!,"000000")) -> #REF! | E5: Asociación | F5: Vacía por transferencia de material | G5: Circular | H5: 4
B6: COL-003 | D6: =IF(H6="","","PL-"&TEXT(#REF!,"000000"))
B7: COL-003 | D7: =IF(H7="","","PL-"&TEXT(#REF!,"000000"))
B8: COL-003 | D8: =IF(H8="","","PL-"&TEXT(#REF!,"000000"))
B9: COL-003 | D9: =IF(H9="","","PL-"&TEXT(#REF!,"000000"))
B10: COL-003 | D10: =IF(H10="","","PL-"&TEXT(#REF!,"000000"))
B11: COL-003 | D11: =IF(H11="","","PL-"&TEXT(#REF!,"000000"))
B12: COL-003 | D12: =IF(H12="","","PL-"&TEXT(#REF!,"000000"))
B13: COL-003 | D13: =IF(H13="","","PL-"&TEXT(#REF!,"000000"))
B14: COL-003 | D14: =IF(H14="","","PL-"&TEXT(#REF!,"000000"))
B15: COL-003 | D15: =IF(H15="","","PL-"&TEXT(#REF!,"000000"))
B16: COL-003 | D16: =IF(H16="","","PL-"&TEXT(#REF!,"000000"))
B17: COL-003 | D17: =IF(H17="","","PL-"&TEXT(#REF!,"000000"))
... B601: COL-003 | D601: =IF(H601="","","PL-"&TEXT(#REF!,"000000"))

Sheet REL_PLACA_PLACA
A1: RelPlacaPlacaID | B1: PlacaOrigenID | C1: PlacaDestinoID | D1: TipoRelacionPlacaID | E1: Observaciones
A2: 1 | B2: HDC-001 | C2: HDC-001-T1 | D2: Derivación taxonómica | E2: Placa tipo creada con ejemplares seleccionados
A3: 2 | B3: HDC-002-P | C3: HDC-002-S | D3: Procesamiento | E3: Material de picking organizado por sorting

Sheet CAT_TIPO_RELACION_PLACA
A1: TipoRelacionPlacaID | B1: Nombre | C1: Descripcion | D1: Activo | E1: Observaciones
A2: 1 | B2: Derivación taxonómica | C2: Placa creada seleccionando ejemplares desde una placa de asociación | D2: Sí | E2: Asociación a Tipo
A3: 2 | B3: Duplicado | C3: Copia física equivalente de una placa existente | D3: Sí | E3: Colecciones referencia
A4: 3 | B4: Repreparación | C4: Nueva preparación desde material original | D4: Sí
A5: 4 | B5: Transferencia de material | C5: Movimiento de material entre placas durante preparación | D5: Sí | E5: Ej. placa vacía a picking
A6: 5 | B6: Reorganización | C6: Cambio de organización del material | D6: Sí | E6: Picking a sorting

Sheet PLACA_TIPO
A1: PlacaTipoID | B1: PlacaID | C1: ClasePTipoID | D1: Observaciones
A2: 1 | B2: PL-002 | C2: Holotipo | D2: Material tipo HDC
A3: 2 | B3: PL-003 | C3: Paratipo | D3: Ejemplares múltiples

Sheet CAT_CLASE_P_TIPO
A1: ClasePTipoID | B1: Nombre | C1: Descripcion | D1: Activo | E1: Observaciones
A2: 1 | B2: Holotipo | C2: Placa tipo que contiene ejemplar holotipo | D2: Sí
A3: 2 | B3: Paratipo | C3: Placa tipo que contiene ejemplar paratipo | D3: Sí
A4: 3 | B4: Topotipo | C4: Placa tipo con material topotipo | D4: Sí
A5: 4 | B5: Homeotipo
A6: 5 | B6: Sin definición

Sheet CAT_CLASE_PLACA
A1: ClasePlacaID | B1: CodigoClase | C1: Nombre | D1: Definicion
A2: 1 | C2: Asociación | D2: Placa con asociación natural o multiespecífica de microfósiles
A3: 2 | C3: Tipo | D3: Placa con ejemplares seleccionados de referencia taxonómica

Sheet CAT_ETAPA_USO_PLACA
A1: EtapaUsoPlacaID | B1: CodigoEtapaUsoPlaca | C1: Nombre | D1: Observaciones
A2: 1 | B2: Vacía-Marcada | C2: Vacia y preparada para organización
A3: 2 | B3: Picking | C3: En uso - material seleccionado
A4: 3 | B4: Sorting | C4: En uso - material organizado
A5: 4 | B5: Vacía-Transf | C5: Vacía por transferencia de material

Sheet CAT_DISENO_PLACA
A1: DisenoPlacaID | B1: Nombre
A2: 1 | B2: Circular
A3: 2 | B3: Rectangular
A4: 3 | B4: Mixta

Sheet CAT_CONFIGURACION_CAVIDADES
A1: ConfiguracionCavidadesID | B1: DisenoPlacaID | C1: TotalCavidades
A2: 1 | B2: 1 | C2: 1
A3: 2 | B3: 1 | C3: 2
A4: 3 | B4: 1 | C4: 3
A5: 4 | B5: 1 | C5: 4
A6: 5 | B6: 2 | C6: 1
A7: 6 | B7: 3 | C7: 2

Sheet CAT_MATERIAL_PLACA
A1: MaterialPlacaID | B1: Nombre
A2: 1 | B2: Cartón
A3: 2 | B3: Plástico

Sheet CAT_COLOR_PLACA
A1: ColorPlacaID | B1: Nombre
A2: 1 | B2: Blanco
A3: 2 | B3: Negro

Sheet CAT_CONFIGURACION_REJILLA
A1: ConfiguracionRejillaID | B1: Nombre | C1: NumeroSubdivisiones | D1: Observaciones
A2: 1 | B2: Rejilla_0 | C2: 0
A3: 2 | B3: Rejilla_10 | C3: 10
A4: 3 | B4: Rejilla_12 | C4: 12
A5: 4 | B5: Rejilla_15 | C5: 15
A6: 5 | B6: Rejilla_20 | C6: 20
A7: 6 | B7: Rejilla_40 | C7: 40
A8: 7 | B8: Rejilla_50 | C8: 50
A9: 8 | B9: Rejilla_60 | C9: 60
A10: 9 | B10: Rejilla_100 | C10: 100

Sheet CAT_TIPO_PROTECCION
A1: TipoProteccionID | B1: Nombre
A2: 1 | B2: Acetato
A3: 2 | B3: Vidrio

Sheet CAT_SISTEMA_ENSAMBLE
A1: SistemaEnsambleID | B1: Nombre
A2: 1 | B2: Acetato deslizante en ranura
A3: 2 | B3: Ensamble de vidrio integrado a marco de cartón
A4: 3 | B4: Ensamble de vidrio movil independiente y marco de aluminio

Sheet CAT_TIPO_AUTOR
A1: TipoAutorID | B1: Nombre | C1: Descripcion
A2: 1 | B2: Persona
A3: 2 | B3: Entidad
A4: 3 | B4: Grupo de trabajo
A5: 4 | B5: Desconocido

Sheet DIC_AUTOR
A1: AutorID | B1: CodigoAutor | C1: NombreAutor | D1: TipoAutorID | E1: EntidadID | F1: EspecialidadID | G1: Observaciones
A2: 1 | C2: Hermann Duque Caro | D2: Persona
A3: 2 | C3: Rosa Ester Navarrete | D3: Persona
A4: 3 | C4: Ecopetrol | D4: Entidad
A5: 4 | C5: ANH | D5: Entidad
A6: 5 | C6: Grupo Bioestratigrafía | D6: Grupo

Sheet CAT_ESPECIALIDAD
A1: EspecialidadID | B1: NombreEspecialidad | C1: Descripcion
A2: 1 | B2: Micropaleontología | C2: Especialista en microfósiles
A3: 2 | B3: Foraminíferos
A4: 3 | B4: Palinología | C4: Polen, esporas, palinomorfos
A5: 4 | B5: Estratigrafía | C5: Análisis estratigráfico
A6: 5 | B6: Cartografía

Sheet REL_PLACA_AUTOR
A1: RelPlacaAutorID | B1: PlacaID | C1: AutorID | D1: RolAutorID | E1: Observaciones
A2: 1 | B2: HDC-001 | C2: Hermann Duque | D2: Identificador | E2: Taxonomía original placa

Sheet REL_DOCUMENTO_AUTOR
A1: RelDocumentoAutorID | B1: DocumentoID | C1: AutorID | D1: RolAutorID | E1: Observaciones
A2: 1 | B2: Informe-001 | C2: Ecopetrol | D2: Autor institucional | E2: Empresa responsable
A3: 2 | B3: Informe-001 | C3: Hermann Duque | D3: Autor técnico | E3: Micropaleontología

Sheet CAT_ROL_AUTOR
A1: RolAutorID | B1: CodigoRolAutor | C1: Nombre | D1: Descripcion | E1: Activo | F1: Observaciones
A2: 1 | B2: AUT-IDENT | C2: Identificador | D2: Realizó identificación taxonómica o bioestratigráfica | E2: Sí
A3: 2 | B3: AUT-TEC | C3: Autor técnico | D3: Autor del contenido científico del documento | E3: No
A4: 3 | B4: AUT-INST | C4: Autor institucional | D4: Entidad responsable del documento
A5: 4 | B5: COAUT | C5: Coautor | D5: Participante en la elaboración del documento
A6: 5 | B6: REV | C6: Revisor | D6: Persona que revisó información científica
A7: 6 | B7: COMP | C7: Compilador | D7: Persona que recopiló información existente
A8: 7 | B8: DIG | C8: Digitalizador | D8: Persona que transformó información física a digital
A9: 8 | B9: DESC | C9: Desconocido | D9: Autor no identificado en la fuente original

Sheet UBICACION_FISICA
A1: UbicacionFisicaID | B1: CodigoUbicacion | C1: PlacaID | D1: MuebleID | E1: SeccionID | F1: ZonaID | G1: NumeroBandeja | H1: MaterialBandejaID | I1: ColumnaBandejaID | J1: PosicionPlaca | K1: CatalogadorID | L1: FechaIngreso | M1: EstadoCatalogacionID | N1: RevisorID | O1: FechaRevision | P1: Observaciones

Sheet CAT_SECCION
A1: SeccionID | B1: CodigoSeccion | C1: Nombre
A2: 1 | C2: Superior
A3: 2 | C3: Inferior

Sheet CAT_ZONA
A1: ZonaID | B1: CodigoZona | C1: Nombre
A2: 1 | C2: Izquierda
A3: 2 | C3: Central
A4: 3 | C4: Derecha

Sheet CAT_MATERIAL_BANDEJA
A1: MaterialBandejaID | B1: CodigoMaterialBandeja | C1: Nombre
A2: 1 | C2: Aluminio
A3: 2 | C3: Madera
A4: 3 | C4: Metálico negro

Sheet CAT_COLUMNA_BANDEJA
A1: ColumnaBandejaID | B1: CodigoColumna | C1: Nombre
A2: 1 | C2: Izquierda
A3: 2 | C3: Derecha

Sheet MARCADO_PLACA
A1: MarcadoPlacaID | B1: PlacaID | C1: TintaNegra | D1: TintaAzul | E1: TintaRoja | F1: TintaVerde | G1: Lapiz | H1: ImpresionNegro | I1: ImpresionAzul | J1: EtiquetaAdherida | K1: Observaciones | L1: CatalogadorID | M1: FechaIngreso | N1: RevisorID | O1: FechaRevision | P1: EstadoCatalogacionID
A2: ="MP-"&TEXT(#REF!,"000000") -> #REF! | B2: {=IFERROR(INDEX(PLACA!$D$2:$D$10000,ROW()-ROW($B$2)+1),"")} | C2: Sí | G2: Sí | K2: Nombres especies en lápiz | L2: CAT-01
A3: ="MP-"&TEXT(#REF!,"000000") -> #REF! | B3: {=IFERROR(INDEX(PLACA!$D$2:$D$10000,ROW()-ROW($B$2)+1),"")}
A4: ="MP-"&TEXT(#REF!,"000000") -> #REF! | B4: {=IFERROR(INDEX(PLACA!$D$2:$D$10000,ROW()-ROW($B$2)+1),"")}
A5: ="MP-"&TEXT(#REF!,"000000") -> #REF! | B5: {=IFERROR(INDEX(PLACA!$D$2:$D$10000,ROW()-ROW($B$2)+1),"")}
A6: ="MP-"&TEXT(#REF!,"000000") -> #REF! | B6: {=IFERROR(INDEX(PLACA!$D$2:$D$10000,ROW()-ROW($B$2)+1),"")}
A7: ="MP-"&TEXT(#REF!,"000000") -> #REF! | B7: {=IFERROR(INDEX(PLACA!$D$2:$D$10000,ROW()-ROW($B$2)+1),"")}
A8: ="MP-"&TEXT(#REF!,"000000") -> #REF! | B8: {=IFERROR(INDEX(PLACA!$D$2:$D$10000,ROW()-ROW($B$2)+1),"")}
A9: ="MP-"&TEXT(#REF!,"000000") -> #REF! | B9: {=IFERROR(INDEX(PLACA!$D$2:$D$10000,ROW()-ROW($B$2)+1),"")}
A10: ="MP-"&TEXT(#REF!,"000000") -> #REF! | B10: {=IFERROR(INDEX(PLACA!$D$2:$D$10000,ROW()-ROW($B$2)+1),"")}
A11: ="MP-"&TEXT(#REF!,"000000") -> #REF! | B11: {=IFERROR(INDEX(PLACA!$D$2:$D$10000,ROW()-ROW($B$2)+1),"")}
A12: ="MP-"&TEXT(#REF!,"000000") -> #REF! | B12: {=IFERROR(INDEX(PLACA!$D$2:$D$10000,ROW()-ROW($B$2)+1),"")}
A13: ="MP-"&TEXT(#REF!,"000000") -> #REF! | B13: {=IFERROR(INDEX(PLACA!$D$2:$D$10000,ROW()-ROW($B$2)+1),"")}
A14: ="MP-"&TEXT(#REF!,"000000") -> #REF! | B14: {=IFERROR(INDEX(PLACA!$D$2:$D$10000,ROW()-ROW($B$2)+1),"")}
... A601: ="MP-"&TEXT(#REF!,"000000") -> #REF! | B601: {=IFERROR(INDEX(PLACA!$D$2:$D$10000,ROW()-ROW($B$2)+1),"")}

Sheet ANOTACION_PLACA
A1: AnotacionID | B1: PlacaID | C1: PosicionAnotacionID | D1: CodigoPosicion | E1: TextoAnotacion | F1: EstadoCatalogacionID | G1: RevisorID | H1: FechaRevision | I1: CatalogadorID | J1: FechaIngreso
A2: 1 | B2: 1 | C2: =IF(E2="","",CHOOSE(MOD(ROW()-2,4)+1,"Izquierda","Derecha","Arriba","Abajo")) -> Izquierda | D2: =IF(E2="","",B2&"_"&C2) -> 1_Izquierda | E2: OCOBO-1 | I2: CAT-01 | J2: 46017
A3: 2 | B3: 1 | C3: =IF(E3="","",CHOOSE(MOD(ROW()-2,4)+1,"Izquierda","Derecha","Arriba","Abajo")) -> Derecha | D3: =IF(E3="","",B3&"_"&C3) -> 1_Derecha | E3: 2460-2470 2500-2510 2660-2670 2730-2740 | I3: CAT-01
A4: 3 | B4: 1 | C4: =IF(E4="","",CHOOSE(MOD(ROW()-2,4)+1,"Izquierda","Derecha","Arriba","Abajo")) -> Arriba | D4: =IF(E4="","",B4&"_"&C4) -> 1_Arriba | E4: 1 2 3 4 | I4: CAT-01
A5: 4 | B5: 1 | C5: =IF(E5="","",CHOOSE(MOD(ROW()-2,4)+1,"Izquierda","Derecha","Arriba","Abajo")) -> Abajo | D5: =IF(E5="","",B5&"_"&C5) -> 1_Abajo | E5: Globigerina
B6: =IF(I6="","",C6&"_"&ANOTACION_PLACA!D6&"_"&TEXT(COUNTIFS($B$2:C6,C6,ANOTACION_PLACA!$C$2:D6,ANOTACION_PLACA!D6,$E$2:I6,"<>"),"00")) | C6: =IF(E6="","",CHOOSE(MOD(ROW()-2,4)+1,"Izquierda","Derecha","Arriba","Abajo")) | D6: =IF(E6="","",B6&"_"&C6)
B7: =IF(I7="","",C7&"_"&ANOTACION_PLACA!D7&"_"&TEXT(COUNTIFS($B$2:C7,C7,ANOTACION_PLACA!$C$2:D7,ANOTACION_PLACA!D7,$E$2:I7,"<>"),"00")) | C7: =IF(E7="","",CHOOSE(MOD(ROW()-2,4)+1,"Izquierda","Derecha","Arriba","Abajo")) | D7: =IF(E7="","",B7&"_"&C7)
B8: =IF(I8="","",C8&"_"&ANOTACION_PLACA!D8&"_"&TEXT(COUNTIFS($B$2:C8,C8,ANOTACION_PLACA!$C$2:D8,ANOTACION_PLACA!D8,$E$2:I8,"<>"),"00")) | C8: =IF(E8="","",CHOOSE(MOD(ROW()-2,4)+1,"Izquierda","Derecha","Arriba","Abajo")) | D8: =IF(E8="","",B8&"_"&C8)
B9: =IF(I9="","",C9&"_"&ANOTACION_PLACA!D9&"_"&TEXT(COUNTIFS($B$2:C9,C9,ANOTACION_PLACA!$C$2:D9,ANOTACION_PLACA!D9,$E$2:I9,"<>"),"00")) | C9: =IF(E9="","",CHOOSE(MOD(ROW()-2,4)+1,"Izquierda","Derecha","Arriba","Abajo")) | D9: =IF(E9="","",B9&"_"&C9)
B10: =IF(I10="","",C10&"_"&ANOTACION_PLACA!D10&"_"&TEXT(COUNTIFS($B$2:C10,C10,ANOTACION_PLACA!$C$2:D10,ANOTACION_PLACA!D10,$E$2:I10,"<>"),"00")) | C10: =IF(E10="","",CHOOSE(MOD(ROW()-2,4)+1,"Izquierda","Derecha","Arriba","Abajo")) | D10: =IF(E10="","",B10&"_"&C10)
B11: =IF(I11="","",C11&"_"&ANOTACION_PLACA!D11&"_"&TEXT(COUNTIFS($B$2:C11,C11,ANOTACION_PLACA!$C$2:D11,ANOTACION_PLACA!D11,$E$2:I11,"<>"),"00")) | C11: =IF(E11="","",CHOOSE(MOD(ROW()-2,4)+1,"Izquierda","Derecha","Arriba","Abajo")) | D11: =IF(E11="","",B11&"_"&C11)
B12: =IF(I12="","",C12&"_"&ANOTACION_PLACA!D12&"_"&TEXT(COUNTIFS($B$2:C12,C12,ANOTACION_PLACA!$C$2:D12,ANOTACION_PLACA!D12,$E$2:I12,"<>"),"00")) | C12: =IF(E12="","",CHOOSE(MOD(ROW()-2,4)+1,"Izquierda","Derecha","Arriba","Abajo")) | D12: =IF(E12="","",B12&"_"&C12)
B13: =IF(I13="","",C13&"_"&ANOTACION_PLACA!D13&"_"&TEXT(COUNTIFS($B$2:C13,C13,ANOTACION_PLACA!$C$2:D13,ANOTACION_PLACA!D13,$E$2:I13,"<>"),"00")) | C13: =IF(E13="","",CHOOSE(MOD(ROW()-2,4)+1,"Izquierda","Derecha","Arriba","Abajo")) | D13: =IF(E13="","",B13&"_"&C13)
B14: =IF(I14="","",C14&"_"&ANOTACION_PLACA!D14&"_"&TEXT(COUNTIFS($B$2:C14,C14,ANOTACION_PLACA!$C$2:D14,ANOTACION_PLACA!D14,$E$2:I14,"<>"),"00")) | C14: =IF(E14="","",CHOOSE(MOD(ROW()-2,4)+1,"Izquierda","Derecha","Arriba","Abajo")) | D14: =IF(E14="","",B14&"_"&C14)
B15: =IF(I15="","",C15&"_"&ANOTACION_PLACA!D15&"_"&TEXT(COUNTIFS($B$2:C15,C15,ANOTACION_PLACA!$C$2:D15,ANOTACION_PLACA!D15,$E$2:I15,"<>"),"00")) | C15: =IF(E15="","",CHOOSE(MOD(ROW()-2,4)+1,"Izquierda","Derecha","Arriba","Abajo")) | D15: =IF(E15="","",B15&"_"&C15)
B16: =IF(I16="","",C16&"_"&ANOTACION_PLACA!D16&"_"&TEXT(COUNTIFS($B$2:C16,C16,ANOTACION_PLACA!$C$2:D16,ANOTACION_PLACA!D16,$E$2:I16,"<>"),"00")) | C16: =IF(E16="","",CHOOSE(MOD(ROW()-2,4)+1,"Izquierda","Derecha","Arriba","Abajo")) | D16: =IF(E16="","",B16&"_"&C16)
B17: =IF(I17="","",C17&"_"&ANOTACION_PLACA!D17&"_"&TEXT(COUNTIFS($B$2:C17,C17,ANOTACION_PLACA!$C$2:D17,ANOTACION_PLACA!D17,$E$2:I17,"<>"),"00")) | C17: =IF(E17="","",CHOOSE(MOD(ROW()-2,4)+1,"Izquierda","Derecha","Arriba","Abajo")) | D17: =IF(E17="","",B17&"_"&C17)
B18: =IF(I18="","",C18&"_"&ANOTACION_PLACA!D18&"_"&TEXT(COUNTIFS($B$2:C18,C18,ANOTACION_PLACA!$C$2:D18,ANOTACION_PLACA!D18,$E$2:I18,"<>"),"00"))
B19: =IF(I19="","",C19&"_"&ANOTACION_PLACA!D19&"_"&TEXT(COUNTIFS($B$2:C19,C19,ANOTACION_PLACA!$C$2:D19,ANOTACION_PLACA!D19,$E$2:I19,"<>"),"00"))
B20: =IF(I20="","",C20&"_"&ANOTACION_PLACA!D20&"_"&TEXT(COUNTIFS($B$2:C20,C20,ANOTACION_PLACA!$C$2:D20,ANOTACION_PLACA!D20,$E$2:I20,"<>"),"00"))
B21: =IF(I21="","",C21&"_"&ANOTACION_PLACA!D21&"_"&TEXT(COUNTIFS($B$2:C21,C21,ANOTACION_PLACA!$C$2:D21,ANOTACION_PLACA!D21,$E$2:I21,"<>"),"00"))
B22: =IF(I22="","",C22&"_"&ANOTACION_PLACA!D22&"_"&TEXT(COUNTIFS($B$2:C22,C22,ANOTACION_PLACA!$C$2:D22,ANOTACION_PLACA!D22,$E$2:I22,"<>"),"00"))
B23: =IF(I23="","",C23&"_"&ANOTACION_PLACA!D23&"_"&TEXT(COUNTIFS($B$2:C23,C23,ANOTACION_PLACA!$C$2:D23,ANOTACION_PLACA!D23,$E$2:I23,"<>"),"00"))
B24: =IF(I24="","",C24&"_"&ANOTACION_PLACA!D24&"_"&TEXT(COUNTIFS($B$2:C24,C24,ANOTACION_PLACA!$C$2:D24,ANOTACION_PLACA!D24,$E$2:I24,"<>"),"00"))
B25: =IF(I25="","",C25&"_"&ANOTACION_PLACA!D25&"_"&TEXT(COUNTIFS($B$2:C25,C25,ANOTACION_PLACA!$C$2:D25,ANOTACION_PLACA!D25,$E$2:I25,"<>"),"00"))
B26: =IF(I26="","",C26&"_"&ANOTACION_PLACA!D26&"_"&TEXT(COUNTIFS($B$2:C26,C26,ANOTACION_PLACA!$C$2:D26,ANOTACION_PLACA!D26,$E$2:I26,"<>"),"00"))
B27: =IF(I27="","",C27&"_"&ANOTACION_PLACA!D27&"_"&TEXT(COUNTIFS($B$2:C27,C27,ANOTACION_PLACA!$C$2:D27,ANOTACION_PLACA!D27,$E$2:I27,"<>"),"00"))
B28: =IF(I28="","",C28&"_"&ANOTACION_PLACA!D28&"_"&TEXT(COUNTIFS($B$2:C28,C28,ANOTACION_PLACA!$C$2:D28,ANOTACION_PLACA!D28,$E$2:I28,"<>"),"00"))
B29: =IF(I29="","",C29&"_"&ANOTACION_PLACA!D29&"_"&TEXT(COUNTIFS($B$2:C29,C29,ANOTACION_PLACA!$C$2:D29,ANOTACION_PLACA!D29,$E$2:I29,"<>"),"00"))
... B540: =IF(I540="","",C540&"_"&ANOTACION_PLACA!D540&"_"&TEXT(COUNTIFS($B$2:C540,C540,ANOTACION_PLACA!$C$2:D540,ANOTACION_PLACA!D540,$E$2:I540,"<>"),"00"))

Sheet CAT_POSICION_ANOTACION
A1: PosicionAnotacionID | B1: Nombre
A2: 1 | B2: Izquierda
A3: 2 | B3: Derecha
A4: 3 | B4: Arriba
A5: 4 | B5: Abajo

Sheet DISPOSICION_MATERIAL
A1: DisposicionMaterialID | B1: PlacaID | C1: MuestraID | D1: CodigoCavidad | E1: NumeroCavidad | F1: TieneMaterial | G1: EstadoMaterial | H1: RecobroCualitativo | I1: EstadoCatalogacionID | J1: RevisorID | K1: FechaRevision | L1: CatalogadorID | M1: FechaIngreso
A2: ="DP-"&TEXT(#REF!,"000000") -> #REF! | B2: =IFERROR(_xlfn.XLOOKUP(#REF!,#REF!,#REF!),"") | C2: =IF(B2=0,0,IFERROR(INDEX(#REF!,MATCH(#REF!,#REF!,0)),0)) -> 0 | D2: C4 | E2: 1 | F2: Sí | G2: Suelto | H2: Escaso (<10%) | L2: CAT-01
A3: ="DP-"&TEXT(#REF!,"000000") -> #REF! | B3: =IFERROR(_xlfn.XLOOKUP(#REF!,#REF!,#REF!),"") | C3: =IF(B3=0,0,IFERROR(INDEX(#REF!,MATCH(#REF!,#REF!,0)),0)) -> 0 | D3: R10 | E3: 2 | L3: CAT-01
A4: ="DP-"&TEXT(#REF!,"000000") -> #REF! | B4: =IFERROR(_xlfn.XLOOKUP(#REF!,#REF!,#REF!),"") | C4: =IF(B4=0,0,IFERROR(INDEX(#REF!,MATCH(#REF!,#REF!,0)),0)) -> 0 | D4: C4 | E4: 1 | L4: CAT-01
A5: ="DP-"&TEXT(#REF!,"000000") -> #REF! | B5: =IFERROR(_xlfn.XLOOKUP(#REF!,#REF!,#REF!),"") | C5: =IF(B5=0,0,IFERROR(INDEX(#REF!,MATCH(#REF!,#REF!,0)),0)) -> 0 | D5: C2 | E5: 4 | L5: CAT-01
A6: ="DP-"&TEXT(#REF!,"000000") -> #REF! | B6: =IFERROR(_xlfn.XLOOKUP(#REF!,#REF!,#REF!),"") | C6: =IF(B6=0,0,IFERROR(INDEX(#REF!,MATCH(#REF!,#REF!,0)),0)) -> 0
A7: ="DP-"&TEXT(#REF!,"000000") -> #REF! | B7: =IFERROR(_xlfn.XLOOKUP(#REF!,#REF!,#REF!),"") | C7: =IF(B7=0,0,IFERROR(INDEX(#REF!,MATCH(#REF!,#REF!,0)),0)) -> 0
A8: ="DP-"&TEXT(#REF!,"000000") -> #REF! | B8: =IFERROR(_xlfn.XLOOKUP(#REF!,#REF!,#REF!),"") | C8: =IF(B8=0,0,IFERROR(INDEX(#REF!,MATCH(#REF!,#REF!,0)),0)) -> 0
A9: ="DP-"&TEXT(#REF!,"000000") -> #REF! | B9: =IFERROR(_xlfn.XLOOKUP(#REF!,#REF!,#REF!),"") | C9: =IF(B9=0,0,IFERROR(INDEX(#REF!,MATCH(#REF!,#REF!,0)),0)) -> 0
A10: ="DP-"&TEXT(#REF!,"000000") -> #REF! | B10: =IFERROR(_xlfn.XLOOKUP(#REF!,#REF!,#REF!),"") | C10: =IF(B10=0,0,IFERROR(INDEX(#REF!,MATCH(#REF!,#REF!,0)),0)) -> 0
A11: ="DP-"&TEXT(#REF!,"000000") -> #REF! | B11: =IFERROR(_xlfn.XLOOKUP(#REF!,#REF!,#REF!),"") | C11: =IF(B11=0,0,IFERROR(INDEX(#REF!,MATCH(#REF!,#REF!,0)),0)) -> 0
A12: ="DP-"&TEXT(#REF!,"000000") -> #REF! | B12: =IFERROR(_xlfn.XLOOKUP(#REF!,#REF!,#REF!),"") | C12: =IF(B12=0,0,IFERROR(INDEX(#REF!,MATCH(#REF!,#REF!,0)),0)) -> 0
A13: ="DP-"&TEXT(#REF!,"000000") -> #REF! | B13: =IFERROR(_xlfn.XLOOKUP(#REF!,#REF!,#REF!),"") | C13: =IF(B13=0,0,IFERROR(INDEX(#REF!,MATCH(#REF!,#REF!,0)),0)) -> 0
A14: ="DP-"&TEXT(#REF!,"000000") -> #REF! | B14: =IFERROR(_xlfn.XLOOKUP(#REF!,#REF!,#REF!),"") | C14: =IF(B14=0,0,IFERROR(INDEX(#REF!,MATCH(#REF!,#REF!,0)),0)) -> 0
A15: ="DP-"&TEXT(#REF!,"000000") -> #REF! | B15: =IFERROR(_xlfn.XLOOKUP(#REF!,#REF!,#REF!),"") | C15: =IF(B15=0,0,IFERROR(INDEX(#REF!,MATCH(#REF!,#REF!,0)),0)) -> 0
A16: ="DP-"&TEXT(#REF!,"000000") -> #REF! | B16: =IFERROR(_xlfn.XLOOKUP(#REF!,#REF!,#REF!),"") | C16: =IF(B16=0,0,IFERROR(INDEX(#REF!,MATCH(#REF!,#REF!,0)),0)) -> 0
A17: ="DP-"&TEXT(#REF!,"000000") -> #REF! | B17: =IFERROR(_xlfn.XLOOKUP(#REF!,#REF!,#REF!),"") | C17: =IF(B17=0,0,IFERROR(INDEX(#REF!,MATCH(#REF!,#REF!,0)),0)) -> 0
... A2401: ="DP-"&TEXT(#REF!,"000000") -> #REF! | B2401: =IFERROR(_xlfn.XLOOKUP(#REF!,#REF!,#REF!),"") | C2401: =IF(B2401=0,0,IFERROR(INDEX(#REF!,MATCH(#REF!,#REF!,0)),0)) -> 0

Sheet CAT_CODIGO_CAVIDAD
A1: CodigoCavidadID | B1: CodigoCavidad | C1: TipoCavidad
A2: 1 | B2: C1 | C2: Circular
A3: 2 | B3: C2 | C3: Circular
A4: 3 | B4: C3 | C4: Circular
A5: 4 | B5: C4 | C5: Circular
A6: 5 | B6: R0 | C6: Rectangular
A7: 6 | B7: R10 | C7: Rectangular
A8: 7 | B8: R12 | C8: Rectangular
A9: 8 | B9: R15 | C9: Rectangular
A10: 9 | B10: R20 | C10: Rectangular
A11: 10 | B11: R40 | C11: Rectangular
A12: 11 | B12: R50 | C12: Rectangular
A13: 12 | B13: R60 | C13: Rectangular
A14: 13 | B14: R100 | C14: Rectangular

Sheet CAT_ESTADO_MATERIAL
A1: EstadoMaterialID | B1: EstadoMaterial
A2: 1 | B2: Suelto
A3: 2 | B3: Pegado

Sheet CAT_RECOBRO_CUALITATIVO
A1: RecobroCualitativoID | B1: RecobroCualitativo | C1: OrdenVisual
A2: 1 | B2: Escaso (<10%) | C2: 1
A3: 2 | B3: Moderado (10-40%) | C3: 2
A4: 3 | B4: Abundante (40-75%) | C4: 3
A5: 4 | B5: Muy abundante (>75%) | C5: 4

Sheet ESTADO_CONSERVACION_INICIAL
A1: EstadoConservacionInicialID | B1: PlacaID | C1: VidrioEstado | D1: AcetatoEstado | E1: MarcoPlacaEstado | F1: PresenciaHongos | G1: CrecimientoCristales | H1: Oxidacion | I1: MaterialFueraCavidad | J1: RiesgoContaminacion | K1: Observaciones | L1: PrioridadIntervencion | M1: EstadoCatalogacionID | N1: RevisorID | O1: FechaRevision | P1: CatalogadorID | Q1: FechaIngreso
A2: =IF(#REF!="","","ECM-"&TEXT(ROW()-1,"000000")) -> #REF! | B2: =IFERROR(#REF!,"") | C2: Intacto | E2: OK | F2: No | G2: No | H2: No | I2: Sí | J2: Sí | K2: El material se salió del orificio porque la placa no estaba dispuesta de manera horizontal | P2: CAT-01
A3: =IF(#REF!="","","ECM-"&TEXT(ROW()-1,"000000")) -> #REF! | B3: =IFERROR(#REF!,"") | C3: Intacto | E3: OK | I3: No | J3: No
A4: =IF(#REF!="","","ECM-"&TEXT(ROW()-1,"000000")) -> #REF! | B4: =IFERROR(#REF!,"")
A5: =IF(#REF!="","","ECM-"&TEXT(ROW()-1,"000000")) -> #REF! | B5: =IFERROR(#REF!,"")
A6: =IF(#REF!="","","ECM-"&TEXT(ROW()-1,"000000")) -> #REF! | B6: =IFERROR(#REF!,"")
A7: =IF(#REF!="","","ECM-"&TEXT(ROW()-1,"000000")) -> #REF! | B7: =IFERROR(#REF!,"")
A8: =IF(#REF!="","","ECM-"&TEXT(ROW()-1,"000000")) -> #REF! | B8: =IFERROR(#REF!,"")
A9: =IF(#REF!="","","ECM-"&TEXT(ROW()-1,"000000")) -> #REF! | B9: =IFERROR(#REF!,"")
A10: =IF(#REF!="","","ECM-"&TEXT(ROW()-1,"000000")) -> #REF! | B10: =IFERROR(#REF!,"")
A11: =IF(#REF!="","","ECM-"&TEXT(ROW()-1,"000000")) -> #REF! | B11: =IFERROR(#REF!,"")
A12: =IF(#REF!="","","ECM-"&TEXT(ROW()-1,"000000")) -> #REF! | B12: =IFERROR(#REF!,"")
A13: =IF(#REF!="","","ECM-"&TEXT(ROW()-1,"000000")) -> #REF! | B13: =IFERROR(#REF!,"")
A14: =IF(#REF!="","","ECM-"&TEXT(ROW()-1,"000000")) -> #REF! | B14: =IFERROR(#REF!,"")
A15: =IF(#REF!="","","ECM-"&TEXT(ROW()-1,"000000")) -> #REF! | B15: =IFERROR(#REF!,"")
... A2401: =IF(#REF!="","","ECM-"&TEXT(ROW()-1,"000000")) -> #REF! | B2401: =IFERROR(#REF!,"")

Sheet CAT_VIDRIO_ESTADO
A1: VidrioEstadoID | B1: VidrioEstado | C1: Observaciones
A2: 1 | B2: Intacto
A3: 2 | B3: Roto
A4: 3 | B4: Ausente
A5: 4 | B5: Restos de caucho cristalizado

Sheet CAT_ACETATO_ESTADO
A1: AcetatoEstadoID | B1: AcetatoEstado | C1: Observaciones
A2: 1 | B2: Intacto
A3: 2 | B3: Corrido
A4: 3 | B4: Ausente

Sheet CAT_MARCO_PLACA_ESTADO
A1: MarcoPlacaEstadoID | B1: MarcoPlacaEstado | C1: Observaciones
A2: 1 | B2: Intacta
A3: 2 | B3: Con caucho cristalizado
A4: 3 | B4: Deformada
A5: 4 | B5: Rota

Sheet CAT_PRIORIDAD_INTERVENCION
A1: PrioridadIntervencionID | B1: Nombre | C1: Observaciones
A2: 1 | B2: Baja
A3: 2 | B3: Media
A4: 3 | B4: Alta
A5: 4 | B5: Crítica

Sheet MUESTRA
A1: MuestraID | B1: NombreMuestraOriginal | C1: CodigoMuestraSistema | D1: OrigenMuestraID | E1: MetodoAdquisicionID | F1: CatalogadorID | G1: FechaIngreso | H1: RevisorID | I1: FechaRevision | J1: EstadoCatalogacionID | K1: Observaciones
A2: 1 | B2: 62-AB-245 | C2: MUE-SUP-0000245 | D2: Superficie
A3: 2
A4: 3
A5: 4
A6: 1
A7: 2
A8: 1
A9: 1
A10: 2

Sheet CAT_METODO_ADQUISICION
A1: MetodoAdquisicionID | B1: OrigenMuestraID | C1: CodigoMetodoAdquisicion | D1: Nombre | E1: Tipo
A2: 1 | B2: 3 | D2: Draga | E2: Lecho marino
A3: 2 | B3: 3 | D3: Box core | E3: Lecho marino
A4: 3 | B4: 3 | D4: Gravity core | E4: Lecho marino
A5: 4 | B5: 3 | D5: Piston core | E5: Lecho marino
A6: 5 | B6: 3 | D6: Multicorer | E6: Lecho marino
A7: 6 | B7: 2 | D7: Perforación rotatoria | E7: Subsuelo
A8: 7 | B8: 2 | D8: Sidewall coring | E8: Subsuelo
A9: 8 | B9: 2 | D9: Conventional coring | E9: Subsuelo
A10: 9 | B10: 1 | D10: Toma manual con martillo | E10: Superficie
A11: 10 | B11: 1 | D11: Barreno manual (auger) | E11: Superficie
A12: 11 | B12: 1 | D12: Canal | E12: Superficie
A13: 12 | B13: 1 | D13: Trinchera | E13: Superficie
A14: 13 | B14: 1 | D14: Núcleo somero manual | E14: Superficie

Sheet CAT_ORIGEN_MUESTRA
A1: OrigenMuestraID | B1: Nombre | C1: Significado
A2: 1 | B2: Superficie | C2: Afloramiento
A3: 2 | B3: Subsuelo | C3: Perforación
A4: 3 | B4: Lecho marino | C4: Sedimento oceánico

Sheet MUESTRA_SUPERFICIE
A1: MuestraSuperficieID | B1: MuestraID | C1: AnoMuestreo | D1: CodigoOriginalMuestra | E1: ColectorID | F1: ConsecutivoCampo | G1: ProfundidadMuestreo | H1: UnidadMedidaID | I1: IGM | J1: NumeroPreparacionLab | K1: Observaciones | L1: PlanchaTopograficaID | M1: LocalizacionGeoreferencialID | N1: SeccionEstratigraficaID | O1: LocalizacionGeograficaID | P1: LocalizacionEspacialID

Sheet LOCALIZACION_GEOREFERENCIAL
A1: LocalizacionGeoreferencialID | B1: MuestraSuperficieID | C1: PoligonalID | D1: PuntoReferencia | E1: Distancia | F1: UnidadMedidaID | G1: Direccion | H1: Azimut | I1: Observaciones
C2: 1 | D2: delta 901 | E2: 80 | F2: m | G2: W | H2: 324

Sheet CAT_COLECTOR
A1: ColectorID | B1: Iniciales | C1: Nombre | D1: Observaciones
A2: 1 | B2: HD | C2: Hermann Duque Caro
A3: 2 | B3: HB | C3: Hans Bürgl
A4: 3 | B4: GGO | C4: Georgina Guzmán Ospitia

Sheet CAT_POLIGONAL
A1: PoligonalID | B1: Nombre | C1: Descripcion
A2: 1 | B2: HD-5B
A3: 2 | B3: HD-15

Sheet SECCION_ESTRATIGRAFICA
A1: SeccionEstratigraficaID | B1: Nombre | C1: LocalizacionGeograficaID | D1: Observaciones
B2: Carmen - Zambrano

Sheet CAT_PLANCHA_TOPOGRAFICA
A1: PlanchaTopograficaID | B1: CodigoPlancha | C1: Nombre | D1: Observaciones
B2: 38 | C2: Plancha 38

Sheet POSICION_ESTRATIGRAFICA
A1: PosicionEstratigraficaID | B1: MuestraID | C1: TextoOriginal | D1: Valor | E1: UnidadMedidaID | F1: TipoRefEstratigraficaID
D2: 30 | E2: m | F2: Sobre la base

Sheet CAT_TIPO_REF_ESTRATIGRAFICA
A1: TipoReferenciaID | B1: Nombre
A2: 1 | B2: Sobre la base
A3: 2 | B3: Bajo la base
A4: 3 | B4: Bajo el techo
A5: 4 | B5: Sobre el techo
A6: 5 | B6: Parte basal
A7: 6 | B7: Parte media
A8: 7 | B8: Parte superior
A9: 8 | B9: Contacto inferior
A10: 9 | B10: Contacto superior
A11: 10 | B11: Otro
A12: 11 | B12: Dentro de la unidad
A13: 12 | B13: Posición desconocida
... A21: 20 | B21: Top de unidad

Sheet CAT_TIPO_PUNTO_MUESTREO
A1: TipoPuntoMuestreoID | B1: Nombre
A2: 1 | B2: Afloramiento
A3: 2 | B3: Pozo somero
A4: 3 | B4: Cantera
A5: 4 | B5: Quebrada
A6: 5 | B6: Carretera
A7: 6 | B7: Río
A8: 7 | B8: Otro

Sheet CAT_TRATAMIENTO_MUESTRA
A1: TratamientoMuestraID | B1: Nombre | C1: Descripcion
A2: 1 | B2: H2O | C2: Lavado con agua
A3: 2 | B3: Top | C3: Lavado con detergente suave Top
A4: 3 | B4: H2O + Top | C4: Lavado con agua y detergente Top
A5: 4 | B5: HCl | C5: Tratamiento ácido clorhídrico
A6: 5 | B6: HF | C6: Tratamiento ácido fluorhídrico
A7: 6 | B7: Tamizado | C7: Separación granulométrica
A8: 7 | B8: Otro | C8: Otro procedimiento

Sheet REL_MUESTRA_TRATAMIENTO
A1: RelMuestraTratamientoID | B1: MuestraID | C1: TratamientoMuestraID | D1: Observaciones

Sheet CAT_FECHA_HISTORICA
A1: FechaHistoricaID | B1: FechaTextoOriginal | C1: FechaInterpretada | D1: TipoFechaHistoricaID | E1: Observaciones
A2: 1 | B2: VIII/24/79 | C2: 29091 | D2: 6 | E2: Tipo aún no determinado

Sheet CAT_TIPO_FECHA_HISTORICA
A1: TipoFechaHistoricaID | B1: Nombre | C1: Descripcion | D1: Activo
A2: 1 | B2: Colecta | C2: cuando se tomó la muestra en campo
A3: 2 | B3: Preparación | C3: preparación de muestra/placa | D3: Sí
A4: 3 | B4: Análisis | C4: estudio micropaleontológico | D4: No
A5: 4 | B5: Montaje | C5: elaboración de placa
A6: 5 | B6: Revisión
A7: 6 | B7: Ingreso colección | C7: entrada al repositorio
A8: 7 | B8: Desconocida

Sheet REL_MUESTRA_FECHA_HISTORICA
A1: RelMuestraFechaHistoricaID | B1: MuestraID | C1: FechaHistoricaID | D1: Observaciones

Sheet CAT_PROYECTO
A1: ProyectoID | B1: Nombre | C1: EntidadID | D1: Observaciones
A2: 1 | B2: Evaluación Estratigráfica RC7 | C2: 12 | D2: Proyecto histórico de exploración

Sheet REL_MUESTRA_PROYECTO
A1: RelMuestraProyectoID | B1: MuestraID | C1: ProyectoID
A2: 1 | B2: M-000123 | C2: 1

Sheet MUESTRA_LECHO_MARINO
A1: MuestraLechoMarinoID | B1: MuestraID | C1: Crucero | D1: Estacion | E1: ProfundidadAgua | F1: UnidadMedidaID | G1: LocalizacionGeograficaID | H1: LocalizacionEspacialID

Sheet MUESTRA_SUBSUELO
A1: MuestraSubsueloID | B1: MuestraID | C1: TipoMuestraSubsueloID | D1: PozoID | E1: TipoIntervaloMuestraID | F1: ProfundidadTope | G1: ProfundidadBase | H1: UnidadMedidaID | I1: IntervaloNucleo

Sheet CAT_UNIDAD_MEDIDA
A1: UnidadMedidaID | B1: Unidad
A2: 1 | B2: pies
A3: 2 | B3: metro
A4: 3 | B4: centimetro
A5: 4 | B5: brazas

Sheet CAT_TIPO_MUESTRA_SUBSUELO
A1: TipoMuestraSubsueloID | B1: Nombre
A2: 1 | B2: Ripios
A3: 2 | B3: Núcleo convencional
A4: 3 | B4: Núcleo de pared

Sheet POZO_REPORTADO
A1: PozoReportadoID | B1: NombreReportado | C1: EstadoRevisionID | D1: CatalogadorID | E1: FechaIngreso | F1: RevisorID | G1: FechaRevision | H1: EstadoCatalogacionID | I1: Observaciones
A2: 1 | B2: Segundo-2 | C2: 1 | I2: Nombre tomado textualmente de la placa

Sheet REL_POZO_REPORTADO_POZO
A1: RelPozoReportadoPozoID | B1: PozoReportadoID | C1: PozoID | D1: Observaciones
A2: 1 | B2: 1 | C2: 15 | D2: Corresponde al pozo oficial El Segundo-2

Sheet POZO
A1: PozoID | B1: CodigoPozo | C1: NombrePozo | D1: CuencaID | E1: LocalizacionGeograficaID | F1: LocalizacionEspacialID | G1: EstadoRevisionID | H1: RevisorID | I1: FechaRevision | J1: Observaciones

Sheet CAT_TIPO_INTERVALO_MUESTRA
A1: TipoIntervaloMuestraID | B1: Tipo
A2: 1 | B2: Puntual
A3: 2 | B3: Intervalo

Sheet POZO_EXPLORATORIO
A1: PozoExploratorioID | B1: PozoID | C1: Operador | D1: EstadoPozo | E1: AnoPerforacion | F1: ProfundidadTotal

Sheet MUESTRA_POZO_EXPLORATORIO
A1: MuestraPozoExploratorioID | B1: CodigoMuestra | C1: MuestraSubsueloID | D1: PozoExploratorioID

Sheet POZO_ESTRATIGRAFICO
A1: PozoEstratigraficoID | B1: PozoID | C1: ProyectoEstratigrafico | D1: Institucion | E1: AnoPerforacion

Sheet MUESTRA_POZO_ESTRATIGRAFICO
A1: MuestraPozoEstratigraficoID | B1: CodigoMuestra | C1: MuestraSubsueloID | D1: PozoEstratigraficoID

Sheet NUCLEO
A1: NucleoID | B1: MuestraSubsueloID | C1: NucleoReportado | D1: NumeroNucleo | E1: ProfundidadTope | F1: ProfundidadBase | G1: UnidadMedidaID | H1: Observaciones
B2: 3 | C2: Sí | D2: 4 | E2: 300 | F2: 400 | G2: 2
B3: 4 | C3: No | D3: null | E3: null | F3: null | G3: 2

Sheet SECCION_NUCLEO
A1: SeccionNucleoID | B1: NucleoID | C1: NumeroSeccion | D1: IntervaloTope | E1: IntervaloBase | F1: UnidadMedidaID | G1: Observaciones
C2: 2 | D2: 0 | E2: 10 | F2: 3

Sheet LOCALIZACION_GEOGRAFICA
A1: LocalizacionGeograficaID | B1: MuestraID | C1: PaisID | D1: DepartamentoID | E1: MunicipioID | F1: CuencaID | G1: ViaReportada | H1: ViaNormID | I1: AccidenteGeograficoReportado | J1: AccidenteGeograficoNormID | K1: KmReferencia | L1: DescripcionLocalidad | M1: NivelDetalleLocalidadID | N1: AnotacionID | O1: EstadoCatalogacionID | P1: RevisorID | Q1: FechaRevision | R1: CatalogadorID | S1: FechaIngreso | T1: Observaciones
A2: 1 | C2: 1 | D2: 20 | G2: El Carmen - Zambrano | K2: 25 | L2: Vía EL Carmen - Zambrano km 25 | M2: Municipio | T2: No se sabe exactamente en qué parte de la vía está el punto

Sheet CAT_PAIS
A1: PaisID | B1: NombrePais

Sheet CAT_DEPARTAMENTO
A1: DepartamentoID | B1: PaisID | C1: NombreDepartamento

Sheet CAT_MUNICIPIO
A1: MunicipioID | B1: DepartamentoID | C1: NombreMunicipio

Sheet CAT_CUENCA
A1: CuencaID | B1: NombreCuenca | C1: CuencaAbrev
A2: 1 | B2: AMAGA | C2: AMA
A3: 2 | B3: AREA NO PROSPECTIVA | C3: ANP
A4: 3 | B4: CAGUAN-PUTUMAYO | C4: CAG-PUT
A5: 4 | B5: CATATUMBO | C5: CAT
A6: 5 | B6: CAUCA-PATIA | C6: CAU-PAT
A7: 6 | B7: CESAR-RANCHERIA | C7: CES-RAN
A8: 7 | B8: CHOCO | C8: CHO
A9: 8 | B9: COLOMBIA | C9: COL
A10: 9 | B10: CORDILLERA-ORIENTAL | C10: COR
A11: 10 | B11: EXTRANJERO | C11: EXTR
A12: 11 | B12: GUAJIRA | C12: GUA
A13: 12 | B13: GUAJIRA-OFFSHORE | C13: GUA-OFF
... A24: 23 | B24: VAUPES-AMAZONAS | C24: VAU-AMAZ

Sheet CAT_VIA_NORM
A1: ViaNormID | B1: NombreNormalizado | C1: Observaciones
A2: 1 | B2: El Carmen - Zambrano
A3: 2 | B3: El Carmen - San Jacinto
A4: 3 | B4: Chalán - Ovejas

Sheet CAT_ACCIDENTE_GEOGRAFICO_NORM
A1: AccidenteGeograficoNormID | B1: Tipo | C1: NombreNormalizado | D1: Observaciones
A2: 1 | B2: Quebrada | C2: La Honda
A3: 2 | B3: Arroyo | C3: Alférez
A4: 3
A5: 4
A6: 5
A7: 6
A8: 7
A9: 8
A10: 9

Sheet CAT_NIVEL_DETALLE_LOCALIDAD
A1: NivelDetalleLocalidadID | B1: Nombre
A2: 1 | B2: País
A3: 2 | B3: Departamento/Estado
A4: 3 | B4: Municipio
A5: 4 | B5: Corregimiento/Vereda
A6: 5 | B6: Localidad
A7: 6 | B7: Pozo
A8: 7 | B8: Afloramiento
A9: 8 | B9: Punto exacto
A10: 9 | B10: Descripción textual aproximada
A11: 10 | B11: Desconocido

Sheet LOCALIZACION_ESPACIAL
A1: LocalizacionEspacialID | B1: LocalizacionGeograficaID | C1: MuestraID | D1: SistemaCoordID | E1: LatitudOriginalTexto | F1: LongitudOriginalTexto | G1: LatitudDecimal | H1: LongitudDecimal | I1: Norte | J1: Este | K1: MetodoEspacialID | L1: FuenteEspacialID | M1: PrecisionEspacialD | N1: EsPrincipal | O1: EsOriginal | P1: EsVerificada | Q1: Precisionm | R1: EstadoCatalogacionID | S1: RevisorID | T1: FechaRevision | U1: CatalogadorID | V1: FechaIngreso | W1: Observaciones
B2: nullable

Sheet CAT_SISTEMA_COORD
A1: SistemaCoordID | B1: Nombre | C1: Tipo | D1: TipoCoordenada | E1: EPSG
A2: 1 | B2: WGS84 Geográficas | C2: Geográfica | D2: LatLong | E2: 4326
A3: 2 | B3: MAGNA-SIRGAS Geográficas | C3: Geográfica | D3: LatLong | E3: 4686
A4: 3 | B4: Bogotá Oeste Oeste | C4: Plana | D4: EsteNorte | E4: 21894
A5: 4 | B5: Bogotá Oeste | C5: Plana | D5: EsteNorte | E5: 21896
A6: 5 | B6: Bogotá Central | C6: Plana | D6: EsteNorte | E6: 21897
A7: 6 | B7: Bogotá Este | C7: Plana | D7: EsteNorte | E7: 21898
A8: 7 | B8: Bogotá Este Este | C8: Plana | D8: EsteNorte | E8: 21900
A9: 8 | B9: MAGNA-SIRGAS UTM 17N | C9: Plana | D9: EsteNorte | E9: 3117
A10: 9 | B10: MAGNA-SIRGAS UTM 18N | C10: Plana | D10: EsteNorte | E10: 3118
A11: 10 | B11: MAGNA-SIRGAS UTM 19N | C11: Plana | D11: EsteNorte | E11: 3119
A12: 11 | B12: Desconocido | C12: Desconocido
A13: 12 | B13: Coordenadas históricas sin datum conocido | C13: Geográfica | D13: Geográfica

Sheet CAT_METODO_ESPACIAL
A1: MetodoEspacialID | B1: NombreMetodoEspacial
A2: 1 | B2: Coordenada GPS
A3: 2 | B3: Conversión de datum
A4: 3 | B4: Georreferenciación de mapa
A5: 4 | B5: Coordenada tomada de publicación
A6: 5 | B6: Coordenada estimada
A7: 6 | B7: Coordenada histórica
A8: 7 | B8: Interpretación
A9: 8 | B9: Coordenada aproximada
A10: 9 | B10: Coordenada convertida

Sheet CAT_FUENTE_ESPACIAL
A1: FuenteEspacialID | B1: Nombre
A2: 1 | B2: Anotación placa
A3: 2 | B3: Informe técnico
A4: 3 | B4: Publicación
A5: 4 | B5: Mapa geológico
A6: 5 | B6: SIG corporativo
A7: 6 | B7: Base ANH
A8: 7 | B8: Conversión automática
A9: 8 | B9: Libreta de campo
A10: 9 | B10: GPS
A11: 10 | B11: Comunicación personal
A12: 11 | B12: Desconocida

Sheet CAT_PRECISION_ESPACIAL
A1: PrecisionEspacialID | B1: NombrePrecisionEspacial | C1: InterpretacionAproximada
A2: 1 | B2: Exacta | C2: < 5 m
A3: 2 | B3: Alta | C3: 5–25 m
A4: 3 | B4: Buena | C4: 25–100 m
A5: 4 | B5: Aproximada | C5: 100–500 m
A6: 5 | B6: Baja | C6: 500 m – 1 km
A7: 6 | B7: Muy baja | C7: > 1 km
A8: 7 | B8: Regional | C8: solo ubicación regional/general
A9: 8 | B9: Desconocida | C9: sin estimación

Sheet CAT_ENTIDAD
A1: NoEntidad | B1: EntidadID | C1: CodigoEntidad | D1: NombreEntidad | E1: TipoEntidad
A2: 1 | B2: 1 | C2: ="ENT-"&TEXT(A2,"0000") -> ENT-0001 | D2: Gran Tierra Energy | E2: Empresa de petróleo y gas
A3: 2 | B3: 2 | C3: ="ENT-"&TEXT(A3,"0000") -> ENT-0002 | D3: Drummond Company Inc. | E3: Empresa minera/energética
A4: 3 | B4: 3 | C4: ="ENT-"&TEXT(A4,"0000") -> ENT-0003 | D4: Conoco (Compañía Continental) | E4: Empresa petrolera
A5: 4 | B5: 4 | C5: ="ENT-"&TEXT(A5,"0000") -> ENT-0004 | D5: Nexen | E5: Empresa petrolera
A6: 5 | B6: 5 | C6: ="ENT-"&TEXT(A6,"0000") -> ENT-0005 | D6: Maurel y Prom | E6: Empresa petrolera
A7: 6 | B7: 6 | C7: ="ENT-"&TEXT(A7,"0000") -> ENT-0006 | D7: Hocol S.A. | E7: Empresa petrolera
A8: 7 | B8: 7 | C8: ="ENT-"&TEXT(A8,"0000") -> ENT-0007 | D8: Paleoflora Ltda. | E8: Empresa de servicios
A9: 8 | B9: 8 | C9: ="ENT-"&TEXT(A9,"0000") -> ENT-0008 | D9: Gulfsands Petroleum | E9: Empresa petrolera
A10: 9 | B10: 9 | C10: ="ENT-"&TEXT(A10,"0000") -> ENT-0009 | D10: Occidental de Colombia | E10: Empresa petrolera
A11: 10 | B11: 10 | C11: ="ENT-"&TEXT(A11,"0000") -> ENT-0010 | D11: Lasmo Oil (Colombia) Ltd. | E11: Empresa petrolera
A12: 11 | B12: 11 | C12: ="ENT-"&TEXT(A12,"0000") -> ENT-0011 | D12: Deep Sea Drilling Project (DSDP) | E12: Programas de investigación internacional
A13: 12 | B13: 12 | C13: ="ENT-"&TEXT(A13,"0000") -> ENT-0012 | D13: Ocean Drilling Program (ODP) | E13: Programas de investigación internacional
... A40: 39 | B40: 39 | C40: ="ENT-"&TEXT(A40,"0000") -> ENT-0039 | D40: Holywell | E40: Empresa
A41: 40 | B41: 40 | C41: ="ENT-"&TEXT(A41,"0000") -> ENT-0040 | D41: Paleosedes
A42: 41 | B42: 41 | C42: ="ENT-"&TEXT(A42,"0000") -> ENT-0041 | D42: IEES
A43: 42 | B43: 42 | C43: ="ENT-"&TEXT(A43,"0000") -> ENT-0042 | D43: Usal
A44: 43 | B44: 43 | C44: ="ENT-"&TEXT(A44,"0000") -> ENT-0043 | D44: Duque-Caro & Cía

Sheet REL_MUESTRA_ENTIDAD
A1: MuestraEntidadID | B1: MuestraID | C1: EntidadID
A2: ="ME-"&TEXT(#REF!,"0000") -> #REF! | B2: MUE-000001 | C2: ENT-0018
A3: ="ME-"&TEXT(#REF!,"0000") -> #REF!
A4: ="ME-"&TEXT(#REF!,"0000") -> #REF!
A5: ="ME-"&TEXT(#REF!,"0000") -> #REF!
A6: ="ME-"&TEXT(#REF!,"0000") -> #REF!
A7: ="ME-"&TEXT(#REF!,"0000") -> #REF!
A8: ="ME-"&TEXT(#REF!,"0000") -> #REF!
A9: ="ME-"&TEXT(#REF!,"0000") -> #REF!
A10: ="ME-"&TEXT(#REF!,"0000") -> #REF!
A11: ="ME-"&TEXT(#REF!,"0000") -> #REF!
A12: ="ME-"&TEXT(#REF!,"0000") -> #REF!
A13: ="ME-"&TEXT(#REF!,"0000") -> #REF!
A14: ="ME-"&TEXT(#REF!,"0000") -> #REF!
... A501: ="ME-"&TEXT(#REF!,"0000") -> #REF!

Sheet DIC_TAXON_REPORTADO
A1: TaxonReportadoID | B1: NombreReportado | C1: AutorTaxonReportado | D1: EstadoRevisionID | E1: CatalogadorID | F1: FechaIngreso | G1: RevisorID | H1: FechaRevision | I1: Observaciones
B2: Globigerina ciperoensis
B3: Globigerina angustiumbilicata
B4: G. bulloides
B5: Globigerinoides spp.

Sheet REL_MUESTRA_TAXON_REPORTADO
A1: MuestraID | B1: TaxonReportadoID | C1: OrdenRegistro | D1: TipoDudaID | E1: ComentarioCatalogador

Sheet DIC_TAXON_NORMALIZADO
A1: TaxonNormalizadoID | B1: NombreNormalizado | C1: AutorTaxonNormalizado | D1: EstadoRevisionID | E1: RevisorID | F1: FechaRevision | G1: Observaciones
A2: 1 | B2: Globigerina ciperoensis | C2: Bolli | D2: 1 | G2: Nombre revisado y estandarizado desde inventario histórico
A3: 2 | B3: Morozovella velascoensis | C3: Cushman | D3: 1 | G3: Corrección ortográfica aplicada

Sheet REL_TAXON_REP_NORM
A1: RelTaxonRepNormID | B1: TaxonReportadoID | C1: TaxonNormalizadoID | D1: Observaciones
A2: 1 | B2: 1 | C2: 5 | D2: Corrección ortográfica
A3: 2 | B3: 2 | C3: 5 | D3: Homologación

Sheet DIC_TAXON_ACTUALIZADO
A1: TaxonActualizadoID | B1: NombreActualizado | C1: AutorTaxonActualizado | D1: FuenteActualizacion | E1: FechaActualizacion | F1: RevisorID | G1: FechaRevision | H1: EstadoRevisionID | I1: Observaciones
A2: 1 | B2: Paragloborotalia ciperoensis | C2: Bolli | D2: WoRMS / literatura taxonómica | E2: 2026 | I2: Cambio nomenclatural
A3: 2 | B3: Morozovella velascoensis | C3: Cushman | D3: Revisión taxonómica actual | E3: 2026 | I3: Nombre vigente

Sheet CAT_TIPO_DUDA
A1: TipoDudaID | B1: Nombre | C1: Descripción
A2: 1 | B2: Nombre ilegible | C2: No es posible interpretar el nombre registrado.
A3: 2 | B3: Nombre parcialmente ilegible | C3: Parte del nombre puede leerse, parte no.
A4: 3 | B4: Código ilegible | C4: El código asociado no puede interpretarse.
A5: 4 | B5: Código incompleto | C5: El código aparece truncado o parcialmente registrado.
A6: 5 | B6: Abreviatura ambigua | C6: La abreviatura puede corresponder a más de una entidad.
A7: 6 | B7: Posible error ortográfico | C7: El nombre parece contener errores de escritura.
A8: 7 | B8: Posible truncamiento | C8: El nombre parece haber sido cortado o incompleto.
A9: 8 | B9: Nombre incompleto | C9: Falta parte del nombre necesario para su identificación.
A10: 9 | B10: Identificación dudosa | C10: Existen dudas sobre la interpretación correcta.
A11: 10 | B11: Entidad no encontrada | C11: No se encontró correspondencia en fuentes de referencia.
A12: 11 | B12: Autor ilegible | C12: El nombre del autor no puede interpretarse.
A13: 12 | B13: Autor ausente | C13: No se reportó autor.
... A17: 16 | B17: Otro | C17: Situación no contemplada en las categorías anteriores.

Sheet CAT_ESTADO_REVISION
A1: EstadoRevisionID | B1: Nombre | C1: Significado
A2: 1 | B2: Sin revisar | C2: Registro capturado por el catalogador
A3: 2 | B3: Revisado | C3: Registro verificado por un especialista
A4: 3 | B4: Normalizado | C4: Existe correspondencia con una forma estandarizada
A5: 4 | B5: Actualizado | C5: Existe correspondencia con una denominación actualmente aceptada
A6: 5 | B6: No encontrado | C6: Sin equivalencia confirmada

Sheet DIC_BIOZONA_REPORTADA
A1: BiozonaReportadaID | B1: NombreReportado | C1: AutorBiozonaReportada | D1: CodigoBiozona | E1: EstadoRevisionID | F1: CatalogadorID | G1: FechaIngreso | H1: RevisorID | I1: FechaRevision | J1: Observaciones
B2: Gn. ciperoensis | C2: Bolli | D2: P22
B3: Globorotalia kugleri | C3: Bolli | D3: N4

Sheet REL_MUESTRA_BIOZONA_REPORTADA
A1: MuestraID | B1: BiozonaReportadaID | C1: OrdenRegistro | D1: TipoDudaID | E1: ComentarioCatalogador

Sheet DIC_BIOZONA_NORMALIZADA
A1: BiozonaNormalizadaID | B1: NombreNormalizado | C1: CodigoBiozona | D1: AutorBiozonaNormalizada | E1: EstadoRevisionID | F1: RevisorID | G1: FechaRevision | H1: Observaciones
A2: 1 | B2: Globigerina ciperoensis Zone | C2: P22 | D2: Bolli | E2: 1 | H2: Nombre expandido y normalizado
A3: 2 | B3: Morozovella velascoensis Zone | C3: P5 | D3: Autor | E3: 1 | H3: Formato estandarizado

Sheet REL_BIOZONA_REP_NORM
A1: RelBiozonaRepNormID | B1: BiozonaReportadaID | C1: BiozonaNormalizadaID | D1: Observaciones
A2: 1 | B2: 1 | C2: 3 | D2: Nombre expandido

Sheet DIC_BIOZONA_ACTUALIZADA
A1: BiozonaActualizadaID | B1: NombreActualizado | C1: CodigoBiozonaActual | D1: FuenteActualizacion | E1: FechaActualizacion | F1: RevisorID | G1: FechaRevision | H1: EstadoRevisionID | I1: Observaciones
A2: 1 | B2: Paragloborotalia ciperoensis Zone | C2: P22 | D2: Escala bioestratigráfica actual | E2: 2026 | I2: Cambio por actualización taxonómica
A3: 2 | B3: Morozovella velascoensis Zone | C3: P5 | D3: Referencia vigente | E3: 2026 | I3: Sin modificación

Sheet REL_BIOZONA_NORM_ACT
A1: RelBiozonaNormActID | B1: BiozonaNormalizadaID | C1: BiozonaActualizadaID | D1: FuenteCambio
A2: 1 | B2: 3 | C2: 4 | D2: Actualización zonación

Sheet DIC_EDAD_REPORTADA
